 * Serving Flask app "run" (lazy loading)
 * Environment: production
   WARNING: This is a development server. Do not use it in a production deployment.
   Use a production WSGI server instead.
 * Debug mode: off
 * Running on http://0.0.0.0:5000/ (Press CTRL+C to quit)
 * Serving Flask app "run" (lazy loading)
 * Environment: production
   WARNING: This is a development server. Do not use it in a production deployment.
   Use a production WSGI server instead.
 * Debug mode: off
 * Running on http://0.0.0.0:5000/ (Press CTRL+C to quit)
150.89.21.114 - - [09/Jan/2020 10:47:45] "GET / HTTP/1.1" 200 -
150.89.21.114 - - [09/Jan/2020 10:47:57] "GET / HTTP/1.1" 200 -
119.229.135.61 - - [09/Jan/2020 10:54:09] "GET / HTTP/1.1" 200 -
150.89.21.114 - - [09/Jan/2020 10:54:27] "GET / HTTP/1.1" 200 -
49.96.23.81 - - [09/Jan/2020 10:54:32] "GET / HTTP/1.1" 200 -
150.89.21.114 - - [09/Jan/2020 10:54:33] "GET / HTTP/1.1" 200 -
150.89.21.114 - - [09/Jan/2020 10:54:33] "GET /favicon.ico HTTP/1.1" 404 -
150.89.21.114 - - [09/Jan/2020 10:54:54] "POST /send HTTP/1.1" 200 -
119.230.69.120 - - [09/Jan/2020 10:55:49] "GET / HTTP/1.1" 200 -
[2020-01-09 10:56:38,842] ERROR in app: Exception on /send [GET]
Traceback (most recent call last):
  File "/home/amosoisin/flask_app/venv/lib/python3.5/site-packages/flask/app.py", line 2446, in wsgi_app
    response = self.full_dispatch_request()
  File "/home/amosoisin/flask_app/venv/lib/python3.5/site-packages/flask/app.py", line 1951, in full_dispatch_request
    rv = self.handle_user_exception(e)
  File "/home/amosoisin/flask_app/venv/lib/python3.5/site-packages/flask/app.py", line 1820, in handle_user_exception
    reraise(exc_type, exc_value, tb)
  File "/home/amosoisin/flask_app/venv/lib/python3.5/site-packages/flask/_compat.py", line 39, in reraise
    raise value
  File "/home/amosoisin/flask_app/venv/lib/python3.5/site-packages/flask/app.py", line 1949, in full_dispatch_request
    rv = self.dispatch_request()
  File "/home/amosoisin/flask_app/venv/lib/python3.5/site-packages/flask/app.py", line 1935, in dispatch_request
    return self.view_functions[rule.endpoint](**req.view_args)
  File "run.py", line 42, in send
    return redirect(url_for("index"), values=values)
TypeError: redirect() got an unexpected keyword argument 'values'
150.89.21.114 - - [09/Jan/2020 10:56:39] "GET /send HTTP/1.1" 500 -
150.89.21.114 - - [09/Jan/2020 10:56:40] "GET /favicon.ico HTTP/1.1" 404 -
[2020-01-09 10:56:45,506] ERROR in app: Exception on /send [GET]
Traceback (most recent call last):
  File "/home/amosoisin/flask_app/venv/lib/python3.5/site-packages/flask/app.py", line 2446, in wsgi_app
    response = self.full_dispatch_request()
  File "/home/amosoisin/flask_app/venv/lib/python3.5/site-packages/flask/app.py", line 1951, in full_dispatch_request
    rv = self.handle_user_exception(e)
  File "/home/amosoisin/flask_app/venv/lib/python3.5/site-packages/flask/app.py", line 1820, in handle_user_exception
    reraise(exc_type, exc_value, tb)
  File "/home/amosoisin/flask_app/venv/lib/python3.5/site-packages/flask/_compat.py", line 39, in reraise
    raise value
  File "/home/amosoisin/flask_app/venv/lib/python3.5/site-packages/flask/app.py", line 1949, in full_dispatch_request
    rv = self.dispatch_request()
  File "/home/amosoisin/flask_app/venv/lib/python3.5/site-packages/flask/app.py", line 1935, in dispatch_request
    return self.view_functions[rule.endpoint](**req.view_args)
  File "run.py", line 42, in send
    return redirect(url_for("index"), values=values)
TypeError: redirect() got an unexpected keyword argument 'values'
150.89.21.114 - - [09/Jan/2020 10:56:45] "GET /send HTTP/1.1" 500 -
[2020-01-09 10:56:47,081] ERROR in app: Exception on /send [GET]
Traceback (most recent call last):
  File "/home/amosoisin/flask_app/venv/lib/python3.5/site-packages/flask/app.py", line 2446, in wsgi_app
    response = self.full_dispatch_request()
  File "/home/amosoisin/flask_app/venv/lib/python3.5/site-packages/flask/app.py", line 1951, in full_dispatch_request
    rv = self.handle_user_exception(e)
  File "/home/amosoisin/flask_app/venv/lib/python3.5/site-packages/flask/app.py", line 1820, in handle_user_exception
    reraise(exc_type, exc_value, tb)
  File "/home/amosoisin/flask_app/venv/lib/python3.5/site-packages/flask/_compat.py", line 39, in reraise
    raise value
  File "/home/amosoisin/flask_app/venv/lib/python3.5/site-packages/flask/app.py", line 1949, in full_dispatch_request
    rv = self.dispatch_request()
  File "/home/amosoisin/flask_app/venv/lib/python3.5/site-packages/flask/app.py", line 1935, in dispatch_request
    return self.view_functions[rule.endpoint](**req.view_args)
  File "run.py", line 42, in send
    return redirect(url_for("index"), values=values)
TypeError: redirect() got an unexpected keyword argument 'values'
150.89.21.114 - - [09/Jan/2020 10:56:47] "GET /send HTTP/1.1" 500 -
150.89.21.114 - - [09/Jan/2020 10:56:55] "GET / HTTP/1.1" 200 -
150.89.21.114 - - [09/Jan/2020 10:57:03] "POST /send HTTP/1.1" 200 -
150.89.21.114 - - [09/Jan/2020 10:57:31] "POST /send HTTP/1.1" 200 -
150.89.21.114 - - [09/Jan/2020 10:58:03] "GET / HTTP/1.1" 200 -
126.35.210.202 - - [09/Jan/2020 10:58:34] "GET / HTTP/1.1" 200 -
119.229.135.61 - - [09/Jan/2020 10:59:04] "POST /send HTTP/1.1" 200 -
150.89.21.114 - - [09/Jan/2020 11:00:07] "GET / HTTP/1.1" 200 -
150.89.21.114 - - [09/Jan/2020 11:00:20] "GET / HTTP/1.1" 200 -
150.89.21.114 - - [09/Jan/2020 11:00:21] "GET /favicon.ico HTTP/1.1" 404 -
